<?xml version="1.0" encoding="UTF-8"?>
<!-- Generated by org.testng.reporters.JUnitReportReporter -->
<testsuite hostname="jorge" name="com.almundo.callcenter.ConcurrentlyCase3Tests" tests="1" failures="1" timestamp="23 Apr 2018 10:58:23 GMT" time="0.136" errors="0">
  <testcase name="concurrentTest" time="0.136" classname="com.almundo.callcenter.ConcurrentlyCase3Tests">
    <failure type="org.testng.TestException" message="
Expected exception org.testng.TestException but got org.testng.TestException: 
Method ConcurrentlyCase3Tests.concurrentTest()[pri:0, instance:com.almundo.callcenter.ConcurrentlyCase3Tests@3abbfa04] should have thrown an exception of class org.testng.TestException">
      <![CDATA[org.testng.TestException: 
Expected exception org.testng.TestException but got org.testng.TestException: 
Method ConcurrentlyCase3Tests.concurrentTest()[pri:0, instance:com.almundo.callcenter.ConcurrentlyCase3Tests@3abbfa04] should have thrown an exception of class org.testng.TestException
	at org.testng.internal.Invoker.handleInvocationResults(Invoker.java:1497)
	at org.testng.internal.Invoker.invokeTestMethods(Invoker.java:1245)
	at org.testng.internal.TestMethodWorker.invokeTestMethods(TestMethodWorker.java:127)
	at org.testng.internal.TestMethodWorker.run(TestMethodWorker.java:111)
	at org.testng.TestRunner.privateRun(TestRunner.java:767)
	at org.testng.TestRunner.run(TestRunner.java:617)
	at org.testng.SuiteRunner.runTest(SuiteRunner.java:334)
	at org.testng.SuiteRunner.runSequentially(SuiteRunner.java:329)
	at org.testng.SuiteRunner.privateRun(SuiteRunner.java:291)
	at org.testng.SuiteRunner.run(SuiteRunner.java:240)
	at org.testng.SuiteRunnerWorker.runSuite(SuiteRunnerWorker.java:52)
	at org.testng.SuiteRunnerWorker.run(SuiteRunnerWorker.java:86)
	at org.testng.TestNG.runSuitesSequentially(TestNG.java:1198)
	at org.testng.TestNG.runSuitesLocally(TestNG.java:1123)
	at org.testng.TestNG.run(TestNG.java:1031)
	at org.testng.remote.AbstractRemoteTestNG.run(AbstractRemoteTestNG.java:114)
	at org.testng.remote.RemoteTestNG.initAndRun(RemoteTestNG.java:251)
	at org.testng.remote.RemoteTestNG.main(RemoteTestNG.java:77)
Caused by: org.testng.TestException: 
Method ConcurrentlyCase3Tests.concurrentTest()[pri:0, instance:com.almundo.callcenter.ConcurrentlyCase3Tests@3abbfa04] should have thrown an exception of class org.testng.TestException
	at org.testng.internal.Invoker.handleInvocationResults(Invoker.java:1512)
	at org.testng.internal.Invoker.invokeMethod(Invoker.java:754)
	at org.testng.internal.Invoker.invokeTestMethod(Invoker.java:901)
	at org.testng.internal.Invoker.invokeTestMethods(Invoker.java:1231)
	... 16 more
]]>
    </failure>
  </testcase> <!-- concurrentTest -->
</testsuite> <!-- com.almundo.callcenter.ConcurrentlyCase3Tests -->
